2021-01-19 14:40:26,018 ERROR: Exception on /auth/login [GET] [in /Users/blake/Desktop/Python-Resume-Projects/microblog/venv/lib/python3.8/site-packages/flask/app.py:1891]
Traceback (most recent call last):
  File "/Users/blake/Desktop/Python-Resume-Projects/microblog/venv/lib/python3.8/site-packages/flask/app.py", line 2447, in wsgi_app
    response = self.full_dispatch_request()
  File "/Users/blake/Desktop/Python-Resume-Projects/microblog/venv/lib/python3.8/site-packages/flask/app.py", line 1952, in full_dispatch_request
    rv = self.handle_user_exception(e)
  File "/Users/blake/Desktop/Python-Resume-Projects/microblog/venv/lib/python3.8/site-packages/flask/app.py", line 1821, in handle_user_exception
    reraise(exc_type, exc_value, tb)
  File "/Users/blake/Desktop/Python-Resume-Projects/microblog/venv/lib/python3.8/site-packages/flask/_compat.py", line 39, in reraise
    raise value
  File "/Users/blake/Desktop/Python-Resume-Projects/microblog/venv/lib/python3.8/site-packages/flask/app.py", line 1950, in full_dispatch_request
    rv = self.dispatch_request()
  File "/Users/blake/Desktop/Python-Resume-Projects/microblog/venv/lib/python3.8/site-packages/flask/app.py", line 1936, in dispatch_request
    return self.view_functions[rule.endpoint](**req.view_args)
  File "/Users/blake/Desktop/Python-Resume-Projects/microblog/app/auth/routes.py", line 18, in login
    db = SQLAlchemy()
NameError: name 'SQLAlchemy' is not defined
2021-01-19 14:40:26,787 ERROR: Exception on /auth/login [GET] [in /Users/blake/Desktop/Python-Resume-Projects/microblog/venv/lib/python3.8/site-packages/flask/app.py:1891]
Traceback (most recent call last):
  File "/Users/blake/Desktop/Python-Resume-Projects/microblog/venv/lib/python3.8/site-packages/flask/app.py", line 2447, in wsgi_app
    response = self.full_dispatch_request()
  File "/Users/blake/Desktop/Python-Resume-Projects/microblog/venv/lib/python3.8/site-packages/flask/app.py", line 1952, in full_dispatch_request
    rv = self.handle_user_exception(e)
  File "/Users/blake/Desktop/Python-Resume-Projects/microblog/venv/lib/python3.8/site-packages/flask/app.py", line 1821, in handle_user_exception
    reraise(exc_type, exc_value, tb)
  File "/Users/blake/Desktop/Python-Resume-Projects/microblog/venv/lib/python3.8/site-packages/flask/_compat.py", line 39, in reraise
    raise value
  File "/Users/blake/Desktop/Python-Resume-Projects/microblog/venv/lib/python3.8/site-packages/flask/app.py", line 1950, in full_dispatch_request
    rv = self.dispatch_request()
  File "/Users/blake/Desktop/Python-Resume-Projects/microblog/venv/lib/python3.8/site-packages/flask/app.py", line 1936, in dispatch_request
    return self.view_functions[rule.endpoint](**req.view_args)
  File "/Users/blake/Desktop/Python-Resume-Projects/microblog/app/auth/routes.py", line 18, in login
    db = SQLAlchemy()
NameError: name 'SQLAlchemy' is not defined
2021-01-19 14:40:27,882 ERROR: Exception on /auth/login [GET] [in /Users/blake/Desktop/Python-Resume-Projects/microblog/venv/lib/python3.8/site-packages/flask/app.py:1891]
Traceback (most recent call last):
  File "/Users/blake/Desktop/Python-Resume-Projects/microblog/venv/lib/python3.8/site-packages/flask/app.py", line 2447, in wsgi_app
    response = self.full_dispatch_request()
  File "/Users/blake/Desktop/Python-Resume-Projects/microblog/venv/lib/python3.8/site-packages/flask/app.py", line 1952, in full_dispatch_request
    rv = self.handle_user_exception(e)
  File "/Users/blake/Desktop/Python-Resume-Projects/microblog/venv/lib/python3.8/site-packages/flask/app.py", line 1821, in handle_user_exception
    reraise(exc_type, exc_value, tb)
  File "/Users/blake/Desktop/Python-Resume-Projects/microblog/venv/lib/python3.8/site-packages/flask/_compat.py", line 39, in reraise
    raise value
  File "/Users/blake/Desktop/Python-Resume-Projects/microblog/venv/lib/python3.8/site-packages/flask/app.py", line 1950, in full_dispatch_request
    rv = self.dispatch_request()
  File "/Users/blake/Desktop/Python-Resume-Projects/microblog/venv/lib/python3.8/site-packages/flask/app.py", line 1936, in dispatch_request
    return self.view_functions[rule.endpoint](**req.view_args)
  File "/Users/blake/Desktop/Python-Resume-Projects/microblog/app/auth/routes.py", line 18, in login
    db = SQLAlchemy()
NameError: name 'SQLAlchemy' is not defined
2021-01-19 14:40:57,455 INFO: Microblog startup [in /Users/blake/Desktop/Python-Resume-Projects/microblog/app/__init__.py:78]
2021-01-19 14:41:07,968 INFO: Microblog startup [in /Users/blake/Desktop/Python-Resume-Projects/microblog/app/__init__.py:78]
2021-01-19 14:41:36,227 INFO: Microblog startup [in /Users/blake/Desktop/Python-Resume-Projects/microblog/app/__init__.py:78]
2021-01-19 14:41:37,899 ERROR: Exception on /auth/login [GET] [in /Users/blake/Desktop/Python-Resume-Projects/microblog/venv/lib/python3.8/site-packages/flask/app.py:1891]
Traceback (most recent call last):
  File "/Users/blake/Desktop/Python-Resume-Projects/microblog/venv/lib/python3.8/site-packages/flask/app.py", line 2447, in wsgi_app
    response = self.full_dispatch_request()
  File "/Users/blake/Desktop/Python-Resume-Projects/microblog/venv/lib/python3.8/site-packages/flask/app.py", line 1952, in full_dispatch_request
    rv = self.handle_user_exception(e)
  File "/Users/blake/Desktop/Python-Resume-Projects/microblog/venv/lib/python3.8/site-packages/flask/app.py", line 1821, in handle_user_exception
    reraise(exc_type, exc_value, tb)
  File "/Users/blake/Desktop/Python-Resume-Projects/microblog/venv/lib/python3.8/site-packages/flask/_compat.py", line 39, in reraise
    raise value
  File "/Users/blake/Desktop/Python-Resume-Projects/microblog/venv/lib/python3.8/site-packages/flask/app.py", line 1950, in full_dispatch_request
    rv = self.dispatch_request()
  File "/Users/blake/Desktop/Python-Resume-Projects/microblog/venv/lib/python3.8/site-packages/flask/app.py", line 1936, in dispatch_request
    return self.view_functions[rule.endpoint](**req.view_args)
  File "/Users/blake/Desktop/Python-Resume-Projects/microblog/app/auth/routes.py", line 18, in login
    db = SQLAlchemy()
NameError: name 'SQLAlchemy' is not defined
2021-01-19 14:41:39,322 ERROR: Exception on /auth/login [GET] [in /Users/blake/Desktop/Python-Resume-Projects/microblog/venv/lib/python3.8/site-packages/flask/app.py:1891]
Traceback (most recent call last):
  File "/Users/blake/Desktop/Python-Resume-Projects/microblog/venv/lib/python3.8/site-packages/flask/app.py", line 2447, in wsgi_app
    response = self.full_dispatch_request()
  File "/Users/blake/Desktop/Python-Resume-Projects/microblog/venv/lib/python3.8/site-packages/flask/app.py", line 1952, in full_dispatch_request
    rv = self.handle_user_exception(e)
  File "/Users/blake/Desktop/Python-Resume-Projects/microblog/venv/lib/python3.8/site-packages/flask/app.py", line 1821, in handle_user_exception
    reraise(exc_type, exc_value, tb)
  File "/Users/blake/Desktop/Python-Resume-Projects/microblog/venv/lib/python3.8/site-packages/flask/_compat.py", line 39, in reraise
    raise value
  File "/Users/blake/Desktop/Python-Resume-Projects/microblog/venv/lib/python3.8/site-packages/flask/app.py", line 1950, in full_dispatch_request
    rv = self.dispatch_request()
  File "/Users/blake/Desktop/Python-Resume-Projects/microblog/venv/lib/python3.8/site-packages/flask/app.py", line 1936, in dispatch_request
    return self.view_functions[rule.endpoint](**req.view_args)
  File "/Users/blake/Desktop/Python-Resume-Projects/microblog/app/auth/routes.py", line 18, in login
    db = SQLAlchemy()
NameError: name 'SQLAlchemy' is not defined
2021-01-19 14:41:39,876 ERROR: Exception on /auth/login [GET] [in /Users/blake/Desktop/Python-Resume-Projects/microblog/venv/lib/python3.8/site-packages/flask/app.py:1891]
Traceback (most recent call last):
  File "/Users/blake/Desktop/Python-Resume-Projects/microblog/venv/lib/python3.8/site-packages/flask/app.py", line 2447, in wsgi_app
    response = self.full_dispatch_request()
  File "/Users/blake/Desktop/Python-Resume-Projects/microblog/venv/lib/python3.8/site-packages/flask/app.py", line 1952, in full_dispatch_request
    rv = self.handle_user_exception(e)
  File "/Users/blake/Desktop/Python-Resume-Projects/microblog/venv/lib/python3.8/site-packages/flask/app.py", line 1821, in handle_user_exception
    reraise(exc_type, exc_value, tb)
  File "/Users/blake/Desktop/Python-Resume-Projects/microblog/venv/lib/python3.8/site-packages/flask/_compat.py", line 39, in reraise
    raise value
  File "/Users/blake/Desktop/Python-Resume-Projects/microblog/venv/lib/python3.8/site-packages/flask/app.py", line 1950, in full_dispatch_request
    rv = self.dispatch_request()
  File "/Users/blake/Desktop/Python-Resume-Projects/microblog/venv/lib/python3.8/site-packages/flask/app.py", line 1936, in dispatch_request
    return self.view_functions[rule.endpoint](**req.view_args)
  File "/Users/blake/Desktop/Python-Resume-Projects/microblog/app/auth/routes.py", line 18, in login
    db = SQLAlchemy()
NameError: name 'SQLAlchemy' is not defined
2021-01-19 14:42:10,730 INFO: Microblog startup [in /Users/blake/Desktop/Python-Resume-Projects/microblog/app/__init__.py:78]
2021-01-19 14:45:34,566 INFO: Microblog startup [in /Users/blake/Desktop/Python-Resume-Projects/microblog/app/__init__.py:78]
2021-01-19 14:52:44,981 INFO: Microblog startup [in /Users/blake/Desktop/Python-Resume-Projects/microblog/app/__init__.py:78]
